Workbook
Name DAM: #REF!
Name DAM: #REF!
Name DAM: #REF!
Name DAM: 'Rechenblatt Koper neu'!$B$4
Name DAM: 'Rechenblatt neu'!$B$4
Name DAM: #REF!
Name DAM: #REF!
Name DAM: #REF!
Name DAMHQ: #REF!
Name DAMHQ: #REF!
Name DAMHQ: #REF!
Name DAMHQ: 'Rechenblatt Koper neu'!$E$4
Name DAMHQ: 'Rechenblatt neu'!$E$4
Name DAMHQ: #REF!
Name DAMHQ: #REF!
Name DAMHQ: #REF!
Name FEBP: #REF!
Name FEBP: #REF!
Name FEBP: #REF!
Name FEBP: 'Rechenblatt Koper neu'!$B$3
Name FEBP: 'Rechenblatt neu'!$B$3
Name FEBP: #REF!
Name FEBP: #REF!
Name FEBP: #REF!
Name FEBP20: #REF!
Name FEBP20: #REF!
Name FEBP20: #REF!
Name FEBP20: 'Rechenblatt Koper neu'!$C$3
Name FEBP20: 'Rechenblatt neu'!$C$3
Name FEBP20: #REF!
Name FEBP20: #REF!
Name FEBP20: #REF!
Name FEBP40: #REF!
Name FEBP40: #REF!
Name FEBP40: #REF!
Name FEBP40: 'Rechenblatt Koper neu'!$D$3
Name FEBP40: 'Rechenblatt neu'!$D$3
Name FEBP40: #REF!
Name FEBP40: #REF!
Name FEBP40: #REF!
Name FEBPHQ: #REF!
Name FEBPHQ: #REF!
Name FEBPHQ: #REF!
Name FEBPHQ: 'Rechenblatt Koper neu'!$E$3
Name FEBPHQ: 'Rechenblatt neu'!$E$3
Name FEBPHQ: #REF!
Name FEBPHQ: #REF!
Name FEBPHQ: #REF!
Name HCM: #REF!
Name HCM: #REF!
Name HCM: #REF!
Name HCM: 'Rechenblatt Koper neu'!$B$7
Name HCM: 'Rechenblatt neu'!$B$7
Name HCM: #REF!
Name HCM: #REF!
Name HCM: #REF!
Name JEA: #REF!
Name JEA: #REF!
Name JEA: #REF!
Name JEA: 'Rechenblatt Koper neu'!$B$6

Sheet Introduction
B7: Europe - Far East Ratesheet
D8: NEW: rate reference mentioned in your email
B9: valid as from 01.12.2025 - 31.01.2026
B10: Special Equipment: FE140000
B11: valid as from 01.01.2026 - 31.01.2026
B12: Reefer: RFT21181
B13: =B9 -> valid as from 01.12.2025 - 31.01.2026
B17: Your rate document is confidential – the contents shall not be disclosed to competitors of OOCL
B19: For forwarders located in Germany, Austria, Czech and Slovakia only
B20: Commodity Cargo all Kinds FAK
B22: Please provide the exact commodity description already at time of booking (no brand/product names).
B23: HS codes would be appreciated
B25: DAY 9 Product
B26: Loops
B27: LL1 | C27: LL2 | D27: LL3 | E27: LL4 | F27: LL5 | G27: LL6 | H27: LL7
B28: ZEE | C28: HAM | D28: RTM | E28: DKK | F28: ANR | G28: HAM | H28: ANR
B29: WVN | C29: ANR | D29: HAM | E29: STN | F29: RTM | G29: RTM | H29: HAM
C30: RTM | D30: ZEE | F30: HAM | H30: RTM
B32: Singapore | C32: Shanghai | D32: Port Klang | E32: Port Klang | F32: Yantian | G32: Colombo | H32: Singapore
B33: Shanghai | C33: Xingang | D33: Shanghai | E33: Ningbo | F33: Port Klang | G33: Singapore | H33: Xingang
B34: Ningbo | C34: Dalian | D34: Xiamen | E34: Pusan | F34: Shanghai | G34: Kaohsiung | H34: Ningbo
B35: Xiamen | C35: Qingdao | D35: Hong Kong | E35: Shanghai | F35: Ningbo | G35: Qingdao | H35: Shanghai
B36: Yantian | C36: Ningbo | D36: Yantian | G36: Shanghai | H36: Yantian
B37: Qingdao | G37: Ningbo
G38: Taipei
G39: Yantian
B43: !!! Rate inquiries - pls send your request to following contact !!!
B45: NVOQuotes@oocl.com
B47: Sales contacts Hamburg | F47: Sales contacts Bremen
B48: Name | C48: Phone | D48: E-Mail | F48: Name | G48: Phone | H48: E-Mail
B49: Anastasia Chernyshov | C49: 040 37 49 60 72 | D49: sales-baumann@OOCL.com | F49: Barbara Triep | G49: 0421 3018 872 | H49: Barbara.Triep@OOCL.com
B50: Andreas Erdmann | C50: 040 37 49 60 41 | D50: Andreas.Erdmann@OOCL.com | F50: Femke Opitz | G50: 0421 3018 776 | H50: Femke.Opitz@OOCL.com
B51: Carolin Albrecht | C51: 040 37 49 60 55 | D51: Carolin.Albrecht@OOCL.com | F51: Hendrik Seifert | G51: 0421 3018 842 | H51: Hendrik.Seifert@OOCL.com
B52: Chiara Hartwich | C52: 040 37 49 60 48 | D52: Chiara.Hartwich@OOCL.com | F52: Julius Blumenstein | G52: 0421 3018 819 | H52: Julius.Blumenstein@OOCL.com
B53: Christian Pick | C53: 040 37 49 60 39 | D53: Christian.Pick@OOCL.com | F53: Kristina Thoma | G53: 0421 3018 820 | H53: Kristina.Thoma@OOCL.com
B54: Finn Baumann | C54: 040 37 49 60 61 | D54: Finn.Baumann@OOCL.com | F54: Laura Nischik | G54: 040 3749 6070 | H54: Laura.Nischik@OOCL.com
B55: Franziska Winkler | C55: 040 37 49 60 59 | D55: Franziska.Winkler@OOCL.com | F55: Marina Gerwers | G55: 0421 3018 828 | H55: Marina.Gerwers@OOCL.com
B56: Jessica Gefcken | C56: 040 37 49 60 46 | D56: sales-winkler@OOCL.com | F56: Patrick Diederich | G56: 0421 3018 764 | H56: Patrick.Diederich@OOCL.com
B57: Jordi Villanes Erquinio | C57: 040 37 49 60 70 | D57: Jordi.Villanes.Erquinio@OOCL.com | F57: Simon Kremin | G57: 0421 3018 763 | H57: Simon.Kremin@OOCL.com
B58: Kerstin Grambow | C58: 040 37 49 60 43 | D58: Kerstin.Grambow@OOCL.com | F58: Thomas Otten | G58: 0421 3018 870 | H58: Thomas.Otten @OOCL.com
...

Sheet Lookup
B1: Index | C1: Base Port | D1: Port Group 1 | E1: Region Group2
B2: =D2 -> DAM | C2: Dammam, Ash Sharqiyah, Saudi Arabia | D2: DAM | E2: MEAST
B3: =D3 -> FEBP | C3: Busan, South Korea | D3: FEBP | E3: n/a
B4: =D4 -> FEBP | C4: Dalian, Dalian, Liaoning, China | D4: FEBP | E4: NCHN
B5: =D5 -> FEBP | C5: Hong Kong, Hong Kong, China | D5: FEBP | E5: n/a
B6: =D6 -> FEBP | C6: Kaohsiung, Taiwan; Taipei, Taiwan | D6: FEBP | E6: n/a
B7: =D7 -> FEBP | C7: Nansha, Guangzhou, Guangdong, China | D7: FEBP | E7: n/a
B8: =D8 -> FEBP | C8: Ningbo, Ningbo, Zhejiang, China | D8: FEBP | E8: NCHN
B9: =D9 -> SIN/PKG | C9: Port Klang, Selangor, Malaysia | D9: SIN/PKG | E9: n/a
B10: =D10 -> FEBP | C10: Qingdao, Qingdao, Shandong, China | D10: FEBP | E10: NCHN
B11: =D11 -> FEBP | C11: Shanghai, China | D11: FEBP | E11: NCHN
B12: =D12 -> SIN/PKG | C12: Singapore, Singapore | D12: SIN/PKG | E12: n/a
B13: =D13 -> FEBP | C13: Taipei, Taiwan | D13: FEBP | E13: n/a
... B19: =D19 -> JED | C19: Jeddah, Makkah, Saudi Arabia | D19: JED | E19: MEAST
B20: FEBP | C20: Jakarta, Indonesia | D20: JKT | E20: n/a
B21: =D21 -> JPBP | C21: Kobe, Hyogo-ken, Japan | D21: JPBP | E21: n/a
B22: =D22 -> JPBP | C22: Yokohama, Kanagawa-ken, Japan | D22: JPBP | E22: n/a
B23: =D23 -> JPBP | C23: Tokyo, Japan | D23: JPBP | E23: n/a
B24: =D24 -> FEBP | C24: Kaohsiung, Taiwan | D24: FEBP | E24: n/a
E25: n/a
B26: =D26 -> SIN/PKG | C26: Port Klang, Selangor, Malaysia; Singapore, Singapore | D26: SIN/PKG | E26: Multiple | F26: * Filter Rechenblatt mit 'contains ;'
B27: =D27 -> FEBP | C27: Kaohsiung, Taiwan; Singapore, Singapore | D27: FEBP | E27: Multiple
B28: =D28 -> FEBP | C28: Ningbo, Ningbo, Zhejiang, China; Port Klang, Selangor, Malaysia | D28: FEBP | E28: Multiple
B29: =D29 -> FEBP | C29: Kaohsiung, Taiwan; Port Klang, Selangor, Malaysia; Singapore, Singapore | D29: FEBP | E29: Multiple
B30: =D30 -> FEBP | C30: Kaohsiung, Taiwan; Qingdao, Qingdao, Shandong, China | D30: FEBP | E30: Multiple
B31: =D31 -> FEBP | C31: Hong Kong, Hong Kong, China; Port Klang, Selangor, Malaysia; Singapore, Singapore | D31: FEBP | E31: Multiple
B32: =D32 -> FEBP | C32: Ningbo, Ningbo, Zhejiang, China; Shanghai, China | D32: FEBP | E32: Multiple
B33: =D33 -> FEBP | C33: Ningbo, Ningbo, Zhejiang, China; Qingdao, Qingdao, Shandong, China; Shanghai, China | D33: FEBP | E33: Multiple
B34: =D34 -> FEBP | C34: Hong Kong, Hong Kong, China; Yantian, Shenzhen, Guangdong, China | D34: FEBP | E34: Multiple
B35: =D35 -> FEBP | C35: Nansha, Guangzhou, Guangdong, China; Yantian, Shenzhen, Guangdong, China | D35: FEBP | E35: Multiple
B36: =D36 -> FEBP | C36: Hong Kong, Hong Kong, China; Port Klang, Selangor, Malaysia; Singapore, Singapore; Vung Tau, Ba Ria Vung Tau, Vietnam | D36: FEBP | E36: Multiple
B37: =D37 -> FEBP | C37: Hong Kong, Hong Kong, China; Nansha, Guangzhou, Guangdong, China | D37: FEBP | E37: Multiple
B38: =D38 -> FEBP | C38: Hong Kong, Hong Kong, China; Kaohsiung, Taiwan; Qingdao, Qingdao, Shandong, China | D38: FEBP | E38: Multiple
... B44: =D44 -> Abu Dhabi | C44: Abu Dhabi, Abu Zabi, United Arab Emirates | D44: Abu Dhabi | E44: MEAST
B45: JPBP | C45: Tokyo, Japan; Yokohama, Kanagawa-ken, Japan | D45: JPBP | E45: n/a
B46: FEBP | C46: Hong Kong, Hong Kong, China; Kaohsiung, Taiwan; Singapore, Singapore | D46: FEBP | E46: n/a
B47: FEBP | C47: Port Klang, Selangor, Malaysia; Shanghai, China | D47: FEBP | E47: Multiple
B48: FEBP | C48: Hong Kong, Hong Kong, China; Kaohsiung, Taiwan; Port Klang, Selangor, Malaysia | D48: FEBP | E48: Multiple
B49: JPBP | C49: Kobe, Hyogo-ken, Japan; Osaka, Japan | D49: JPBP | E49: n/a
B50: FEBP | C50: Hong Kong, Hong Kong, China; Nansha, Guangzhou, Guangdong, China; Shekou, Shenzhen, Guangdong, China; Yantian, Shenzhen, Guangdong, China | D50: FEBP | E50: n/a
...

Sheet Rechenblatt neu
B1: check ports under tab 'Lookup'
B2: direct calls - port group | C2: 20' | D2: 40' | E2: 40'HQ | J2: PUSAN TAD via NIN statt SHA
B3: FEBP | C3: 25 | D3: 25 | E3: 25 | G3: = NUR HIER EINTRAGEN
B4: DAM | C4: 925 | D4: 1125 | E4: 1125 | J4: Nhava via Colombo add on USD400/CTR
B5: JED
B6: JEA | C6: 575 | D6: 575 | E6: 575 | J6: Haldia | K6: 20GP = same rate as Kolkata
B7: HCM | C7: 175 | D7: 300 | E7: 300 | K7: 40'CTR = same rate as Kolkata
B8: JKT | C8: 300 | D8: 425 | E8: 425 | J8: Vizag | K8: Ratebuilder
B9: SIN/PKG | C9: =FEBP20 -> 25 | D9: =FEBP40 -> 25 | E9: =D9 -> 25 | J9: Kolkata | K9: Ratebuilder
B10: YOK | C10: 400 | D10: 400 | E10: 400
B11: JPBP | C11: 400 | D11: 400 | E11: 400
B12: Abu Dhabi | C12: 575 | D12: 575 | E12: 575 | J12: Forrestfield | K12: 20GP = + USD305
K13: 40'CTR = + USD405
B15: ABU DHABI nur IP1
A16: Middle East | G16: OVER (BP Rate) | H16: TAD20ft | I16: TAD40ft | J16: TAD40HQ | K16: Rate 20ft | L16: Rate 40ft | M16: Rate 40HQ
A17: Port group | B17: TAD's Far East vom Jul 24 - sortiert nach HUB-Port
A18: =VLOOKUP(G18,Lookup!C:D,2,0) -> JEA | B18: Ajman, United Arab Emirates | C18: CY | G18: Jebel Ali, Dubai, United Arab Emirates | H18: 300 | I18: 450 | J18: 450 | K18: =IF(H18<>"",VLOOKUP($A18,$B$3:$E$12,2,FALSE)+H18,"--") -> 875 | L18: =IF(I18<>"",VLOOKUP($A18,$B$3:$E$12,3,FALSE)+I18,"--") -> 1025 | M18: =L18 -> 1025
A19: =VLOOKUP(G19,Lookup!C:D,2,0) -> JEA | B19: Al Hidd, Muharraq Governorate, Bahrain | C19: CY | G19: Jebel Ali, Dubai, United Arab Emirates | H19: 250 | I19: 350 | J19: 350 | K19: =IF(H19<>"",VLOOKUP($A19,$B$3:$E$12,2,FALSE)+H19,"--") -> 825 | L19: =IF(I19<>"",VLOOKUP($A19,$B$3:$E$12,3,FALSE)+I19,"--") -> 925 | M19: =L19 -> 925
A20: JEA | B20: Al Shuwaikh, Al Asamah, Kuwait | C20: CY | G20: Jebel Ali, Dubai, United Arab Emirates | H20: 325 | I20: 575 | J20: 575 | K20: =IF(H20<>"",VLOOKUP($A20,$B$3:$E$12,2,FALSE)+H20,"--") -> 900 | L20: =IF(I20<>"",VLOOKUP($A20,$B$3:$E$12,3,FALSE)+I20,"--") -> 1150 | M20: =L20 -> 1150
A21: DAM | B21: Ar Riyad, Ar Riyad, Saudi Arabia | C21: CY | G21: Dammam, Ash Sharqiyah, Saudi Arabia | H21: 250 | I21: 450 | J21: 450 | K21: =IF(H21<>"",VLOOKUP($A21,$B$3:$E$12,2,FALSE)+H21,"--") -> 1175 | L21: =IF(I21<>"",VLOOKUP($A21,$B$3:$E$12,3,FALSE)+I21,"--") -> 1575 | M21: =L21 -> 1575
A22: =VLOOKUP(G22,Lookup!C:D,2,0) -> JEA | B22: Dammam, Ash Sharqiyah, Saudi Arabia | C22: CY | G22: Jebel Ali, Dubai, United Arab Emirates | H22: 350 | I22: 550 | J22: 550 | K22: =IF(H22<>"",VLOOKUP($A22,$B$3:$E$12,2,FALSE)+H22,"--") -> 925 | L22: =IF(I22<>"",VLOOKUP($A22,$B$3:$E$12,3,FALSE)+I22,"--") -> 1125 | M22: =L22 -> 1125
A23: =VLOOKUP(G23,Lookup!C:D,2,0) -> JEA | B23: Hamad port, Al Wakrah, Qatar | C23: CY | G23: Jebel Ali, Dubai, United Arab Emirates | H23: 375 | I23: 475 | J23: 475 | K23: =IF(H23<>"",VLOOKUP($A23,$B$3:$E$12,2,FALSE)+H23,"--") -> 950 | L23: =IF(I23<>"",VLOOKUP($A23,$B$3:$E$12,3,FALSE)+I23,"--") -> 1050 | M23: =L23 -> 1050
A24: =VLOOKUP(G24,Lookup!C:D,2,0) -> JEA | B24: Kuwait, Al Asamah, Kuwait | C24: CY | G24: Jebel Ali, Dubai, United Arab Emirates | H24: 325 | I24: 575 | J24: 575 | K24: =IF(H24<>"",VLOOKUP($A24,$B$3:$E$12,2,FALSE)+H24,"--") -> 900 | L24: =IF(I24<>"",VLOOKUP($A24,$B$3:$E$12,3,FALSE)+I24,"--") -> 1150 | M24: =L24 -> 1150
A25: =VLOOKUP(G25,Lookup!C:D,2,0) -> JEA | B25: Sharjah, United Arab Emirates | C25: CY | G25: Jebel Ali, Dubai, United Arab Emirates | H25: 150 | I25: 275 | J25: 275 | K25: =IF(H25<>"",VLOOKUP($A25,$B$3:$E$12,2,FALSE)+H25,"--") -> 725 | L25: =IF(I25<>"",VLOOKUP($A25,$B$3:$E$12,3,FALSE)+I25,"--") -> 850 | M25: =L25 -> 850
A26: =VLOOKUP(G26,Lookup!C:D,2,0) -> JEA | B26: Shuaiba, Al Ahmadi, Kuwait | C26: CY | G26: Jebel Ali, Dubai, United Arab Emirates | H26: 325 | I26: 550 | J26: 550 | K26: =IF(H26<>"",VLOOKUP($A26,$B$3:$E$12,2,FALSE)+H26,"--") -> 900 | L26: =IF(I26<>"",VLOOKUP($A26,$B$3:$E$12,3,FALSE)+I26,"--") -> 1125 | M26: =L26 -> 1125
A27: =VLOOKUP(G27,Lookup!C:D,2,0) -> JEA | B27: Sohar, Al Batinah North Governorate, Oman | C27: CY | G27: Jebel Ali, Dubai, United Arab Emirates | H27: 250 | I27: 350 | J27: 350 | K27: =IF(H27<>"",VLOOKUP($A27,$B$3:$E$12,2,FALSE)+H27,"--") -> 825 | L27: =IF(I27<>"",VLOOKUP($A27,$B$3:$E$12,3,FALSE)+I27,"--") -> 925 | M27: =L27 -> 925
A28: =VLOOKUP(G28,Lookup!C:D,2,0) -> JEA | B28: Umm Al Quwain, United Arab Emirates | C28: CY | G28: Jebel Ali, Dubai, United Arab Emirates | H28: 350 | I28: 600 | J28: 600 | K28: =IF(H28<>"",VLOOKUP($A28,$B$3:$E$12,2,FALSE)+H28,"--") -> 925 | L28: =IF(I28<>"",VLOOKUP($A28,$B$3:$E$12,3,FALSE)+I28,"--") -> 1175 | M28: =L28 -> 1175
B31: TAD's Far East vom Aug 24 - sortiert nach HUB-Port
A32: Asia Port Group | B32: Location | C32: Mode | D32: T/S Via | G32: OVER (BP Rate) | H32: TAD20ft | I32: TAD40ft | J32: TAD40HQ | K32: Rate 20ft | L32: Rate 40ft | M32: Rate 40HQ
A33: =VLOOKUP(G33,Lookup!C:D,2,0) -> JPBP | B33: Akita, Akita, Japan | C33: CY | D33: Hibiki, Fukuoka, Japan | E33: GC; DG | G33: Kobe, Hyogo-ken, Japan | H33: 550 | I33: 750 | J33: 750 | K33: =IF(H33<>"",VLOOKUP($A33,$B$3:$E$12,2,FALSE)+H33,"--") -> 950 | L33: =IF(I33<>"",VLOOKUP($A33,$B$3:$E$11,3,FALSE)+I33,"--") -> 1150 | M33: =IF(J33<>"",VLOOKUP($A33,$B$3:$E$11,4,FALSE)+J33,"--") -> 1150
A34: =VLOOKUP(G34,Lookup!C:D,2,0) -> FEBP | B34: Anji, Huzhou, Zhejiang, China | C34: CY | D34: Shanghai, China | E34: GC; DG | G34: Shanghai, China | H34: 175 | I34: 300 | J34: 300 | K34: =IF(H34<>"",VLOOKUP($A34,$B$3:$E$12,2,FALSE)+H34,"--") -> 200 | L34: =IF(I34<>"",VLOOKUP($A34,$B$3:$E$11,3,FALSE)+I34,"--") -> 325 | M34: =IF(J34<>"",VLOOKUP($A34,$B$3:$E$11,4,FALSE)+J34,"--") -> 325
A35: =VLOOKUP(G35,Lookup!C:D,2,0) -> FEBP | B35: Anqing, Anqing, Anhui, China | C35: CY | D35: Shanghai, China | E35: GC; DG | G35: Shanghai, China | H35: 200 | I35: 300 | J35: 300 | K35: =IF(H35<>"",VLOOKUP($A35,$B$3:$E$12,2,FALSE)+H35,"--") -> 225 | L35: =IF(I35<>"",VLOOKUP($A35,$B$3:$E$11,3,FALSE)+I35,"--") -> 325 | M35: =IF(J35<>"",VLOOKUP($A35,$B$3:$E$11,4,FALSE)+J35,"--") -> 325
A36: =VLOOKUP(G36,Lookup!C:D,2,0) -> SIN/PKG | B36: Bandar Lampung, Lampung, Indonesia | C36: CY | D36: Singapore, Singapore | E36: GC; DG | G36: Singapore, Singapore | H36: 425 | I36: 700 | J36: 700 | K36: =IF(H36<>"",VLOOKUP($A36,$B$3:$E$12,2,FALSE)+H36,"--") -> 450 | L36: =IF(I36<>"",VLOOKUP($A36,$B$3:$E$11,3,FALSE)+I36,"--") -> 725 | M36: =IF(J36<>"",VLOOKUP($A36,$B$3:$E$11,4,FALSE)+J36,"--") -> 725
A37: =VLOOKUP(G37,Lookup!C:D,2,0) -> SIN/PKG | B37: Bangkok, Thailand | C37: CY | D37: Port Klang, Selangor, Malaysia; Singapore, Singapore | E37: GC; DG | G37: Port Klang, Selangor, Malaysia; Singapore, Singapore | H37: 225 | I37: 350 | J37: 350 | K37: =IF(H37<>"",VLOOKUP($A37,$B$3:$E$12,2,FALSE)+H37,"--") -> 250 | L37: =IF(I37<>"",VLOOKUP($A37,$B$3:$E$11,3,FALSE)+I37,"--") -> 375 | M37: =IF(J37<>"",VLOOKUP($A37,$B$3:$E$11,4,FALSE)+J37,"--") -> 375
A38: =VLOOKUP(G38,Lookup!C:D,2,0) -> FEBP | B38: Beihai, Beihai, Guangxi, China | C38: CY | D38: Hong Kong, Hong Kong, China | E38: GC; DG | G38: Hong Kong, Hong Kong, China | H38: 350 | I38: 550 | J38: 550 | K38: =IF(H38<>"",VLOOKUP($A38,$B$3:$E$12,2,FALSE)+H38,"--") -> 375 | L38: =IF(I38<>"",VLOOKUP($A38,$B$3:$E$11,3,FALSE)+I38,"--") -> 575 | M38: =IF(J38<>"",VLOOKUP($A38,$B$3:$E$11,4,FALSE)+J38,"--") -> 575
A39: =VLOOKUP(G39,Lookup!C:D,2,0) -> FEBP | B39: Beijiao, Shunde, Guangdong, China | C39: CY | D39: Hong Kong, Hong Kong, China | E39: GC; DG | G39: Hong Kong, Hong Kong, China; Nansha, Guangzhou, Guangdong, China | H39: 125 | I39: 225 | J39: 225 | K39: =IF(H39<>"",VLOOKUP($A39,$B$3:$E$12,2,FALSE)+H39,"--") -> 150 | L39: =IF(I39<>"",VLOOKUP($A39,$B$3:$E$11,3,FALSE)+I39,"--") -> 250 | M39: =IF(J39<>"",VLOOKUP($A39,$B$3:$E$11,4,FALSE)+J39,"--") -> 250
A40: =VLOOKUP(G40,Lookup!C:D,2,0) -> SIN/PKG | B40: Belawan, Sumatera Utara, Indonesia | C40: CY | D40: Port Klang, Selangor, Malaysia; Singapore, Singapore | E40: GC; DG | G40: Port Klang, Selangor, Malaysia; Singapore, Singapore | H40: 300 | I40: 475 | J40: 475 | K40: =IF(H40<>"",VLOOKUP($A40,$B$3:$E$12,2,FALSE)+H40,"--") -> 325 | L40: =IF(I40<>"",VLOOKUP($A40,$B$3:$E$11,3,FALSE)+I40,"--") -> 500 | M40: =IF(J40<>"",VLOOKUP($A40,$B$3:$E$11,4,FALSE)+J40,"--") -> 500
A41: =VLOOKUP(G41,Lookup!C:D,2,0) -> SIN/PKG | B41: Bintulu, Sarawak, Malaysia | C41: CY | D41: Port Klang, Selangor, Malaysia | E41: GC; DG | G41: Port Klang, Selangor, Malaysia | H41: 750 | I41: 1350 | J41: 1350 | K41: =IF(H41<>"",VLOOKUP($A41,$B$3:$E$12,2,FALSE)+H41,"--") -> 775 | L41: =IF(I41<>"",VLOOKUP($A41,$B$3:$E$11,3,FALSE)+I41,"--") -> 1375 | M41: =IF(J41<>"",VLOOKUP($A41,$B$3:$E$11,4,FALSE)+J41,"--") -> 1375
A42: FEBP | B42: Bintulu, Sarawak, Malaysia | C42: CY | D42: Singapore, Singapore | E42: GC; DG | G42: Singapore, Singapore | H42: 1050 | I42: 1850 | J42: 1850 | K42: =IF(H42<>"",VLOOKUP($A42,$B$3:$E$12,2,FALSE)+H42,"--") -> 1075 | L42: =IF(I42<>"",VLOOKUP($A42,$B$3:$E$11,3,FALSE)+I42,"--") -> 1875 | M42: =IF(J42<>"",VLOOKUP($A42,$B$3:$E$11,4,FALSE)+J42,"--") -> 1875
A43: =VLOOKUP(G43,Lookup!C:D,2,0) -> FEBP | B43: Busan, South Korea | C43: CY | D43: Ningbo, Ningbo, Zhejiang, China | E43: GC; DG | G43: Ningbo, Ningbo, Zhejiang, China | H43: 45 | I43: 65 | J43: 65 | K43: =IF(H43<>"",VLOOKUP($A43,$B$3:$E$12,2,FALSE)+H43,"--") -> 70 | L43: =IF(I43<>"",VLOOKUP($A43,$B$3:$E$11,3,FALSE)+I43,"--") -> 90 | M43: =IF(J43<>"",VLOOKUP($A43,$B$3:$E$11,4,FALSE)+J43,"--") -> 90
...

Sheet Far East+Japan
B3: Orient Overseas Container Line Ltd.
B4: =Introduction!D8 -> NEW: rate reference mentioned in your email
B5: =Introduction!B9 -> valid as from 01.12.2025 - 31.01.2026
B9: Far East direct calls | C9: GATE IN subject to below + destination charges
B10: POL | C10: POD | D10: 20' Box | E10: 40' Box | F10: 40' HQ | G10: GC;DG | H10: Loop
B11: HAM / RTM / ANR | C11: Dalian | D11: ='Rechenblatt neu'!FEBP20 -> 25 | E11: ='Rechenblatt neu'!FEBP40 -> 25 | F11: ='Rechenblatt neu'!FEBPHQ -> 25 | G11: GC;DG | H11: LL2
B12: HAM / RTM / ZEE | C12: Hong Kong | D12: ='Rechenblatt neu'!FEBP20 -> 25 | E12: ='Rechenblatt neu'!FEBP40 -> 25 | F12: ='Rechenblatt neu'!FEBPHQ -> 25 | G12: GC;DG | H12: LL3
B13: HAM / RTM | C13: Kaohsiung | D13: ='Rechenblatt neu'!FEBP20 -> 25 | E13: ='Rechenblatt neu'!FEBP40 -> 25 | F13: ='Rechenblatt neu'!FEBPHQ -> 25 | G13: GC;DG | H13: LL6
B14: HAM / WVN / RTM / ANR / ZEE | C14: Nansha ( in t/s via PKG/SIN) | D14: ='Rechenblatt neu'!FEBP20 -> 25 | E14: ='Rechenblatt neu'!FEBP40 -> 25 | F14: ='Rechenblatt neu'!FEBPHQ -> 25 | G14: GC;DG | H14: LL1; LL3; LL5; LL6; LL7
B15: HAM / WVN / RTM / ANR / ZEE | C15: Ningbo | D15: ='Rechenblatt neu'!FEBP20 -> 25 | E15: ='Rechenblatt neu'!FEBP40 -> 25 | F15: ='Rechenblatt neu'!FEBPHQ -> 25 | G15: GC;DG | H15: LL1; LL2; LL5; LL6; LL7
B16: HAM / RTM / ANR | C16: Port Klang | D16: ='Rechenblatt neu'!FEBP20 -> 25 | E16: ='Rechenblatt neu'!FEBP40 -> 25 | F16: ='Rechenblatt neu'!FEBPHQ -> 25 | G16: GC;DG | H16: LL3; LL5
B17: HAM / WVN / RTM / ANR / ZEE | C17: Qingdao | D17: ='Rechenblatt neu'!FEBP20 -> 25 | E17: ='Rechenblatt neu'!FEBP40 -> 25 | F17: ='Rechenblatt neu'!FEBPHQ -> 25 | G17: GC;DG | H17: LL1; LL2; LL6
B18: HAM / WVN / RTM / ANR / ZEE | C18: Shanghai | D18: ='Rechenblatt neu'!FEBP20 -> 25 | E18: ='Rechenblatt neu'!FEBP40 -> 25 | F18: ='Rechenblatt neu'!FEBPHQ -> 25 | G18: GC;DG | H18: LL1; LL3; LL2; LL6; LL7
B19: HAM / WVN / RTM / ANR / ZEE | C19: Shekou ( in t/s via PKG/SIN) | D19: ='Rechenblatt neu'!FEBP20 -> 25 | E19: ='Rechenblatt neu'!FEBP40 -> 25 | F19: ='Rechenblatt neu'!FEBPHQ -> 25 | G19: GC;DG | H19: LL1; LL3; LL5; LL6; LL7
B20: HAM / WVN / RTM / ANR / ZEE | C20: Singapore | D20: ='Rechenblatt neu'!FEBP20 -> 25 | E20: ='Rechenblatt neu'!FEBP40 -> 25 | F20: ='Rechenblatt neu'!FEBPHQ -> 25 | G20: GC;DG | H20: LL1; LL6; LL7
B21: HAM / RTM | C21: Taipei | D21: ='Rechenblatt neu'!FEBP20 -> 25 | E21: ='Rechenblatt neu'!FEBP40 -> 25 | F21: ='Rechenblatt neu'!FEBPHQ -> 25 | G21: GC;DG | H21: LL6
B22: WVN / ZEE / HAM / RTM | C22: Xiamen | D22: ='Rechenblatt neu'!FEBP20 -> 25 | E22: ='Rechenblatt neu'!FEBP40 -> 25 | F22: ='Rechenblatt neu'!FEBPHQ -> 25 | G22: GC;DG | H22: LL1; LL3
... B24: HAM / WVN / RTM / ANR / ZEE | C24: Yantian | D24: ='Rechenblatt neu'!FEBP20 -> 25 | E24: ='Rechenblatt neu'!FEBP40 -> 25 | F24: ='Rechenblatt neu'!FEBPHQ -> 25 | G24: GC;DG | H24: LL1; LL3; LL5; LL6; LL7
B26: Freetime at Origin for destination CHINA / INDONESIA / SINGAPORE / MALAYSIA / TAIWAN / VIETNAM / THAILAND
B27: ANR / RTM / WHV / ZEE / HAM : 14 cal days DD combined (2in1)
B29: Freetime at Destination:
B30: CHINA / INDONESIA / SINGAPORE / VIETNAM / HONG KONG : 14 cal days DD combined (2in1)
B31: MALAYSIA / TAIWAN / THAILAND : 14 cal days DETENTION - sub to QUAY RENT
B33: Far East direct calls & transshipments | C33: GATE IN subject to below + destination charges (all charges prepaid!)
B34: POL | C34: POD | D34: 20' Box | E34: 40' Box | F34: 40' HQ | G34: GC;DG | H34: Loop
B35: WVN / HAM / ZEE / RTM | C35: Chattogram (via Port Klang / Singapore / Colombo) | D35: 1300 | E35: 1600 | F35: 1600 | G35: GC;DG | H35: LL1; LL3; LL5; LL6; LL7
B36: HAM / RTM | C36: Colombo | D36: 550 | E36: 550 | F36: 550 | G36: GC;DG | H36: LL6
B38: Japan via transshipment | C38: GATE IN subject to below + destination charges
B39: POL | C39: POD | D39: 20' Box | E39: 40' Box | F39: 40' HQ | G39: GC;DG | H39: Loop
B40: WVN / HAM / RTM / ANR / ZEE | C40: Tokyo | D40: ='Rechenblatt neu'!$C11 -> 400 | E40: ='Rechenblatt neu'!D11 -> 400 | F40: =E40 -> 400 | G40: GC;DG | H40: LL1; LL2 ; LL3; LL5; LL6; LL7
B41: WVN / HAM / RTM / ANR / ZEE | C41: Kobe | D41: =D40 -> 400 | E41: =E40 -> 400 | F41: =E41 -> 400 | G41: GC;DG | H41: LL1; LL2 ; LL3; LL5; LL6; LL7
B42: WVN / HAM / RTM / ANR / ZEE | C42: Nagoya | D42: =D41 -> 400 | E42: =E41 -> 400 | F42: =E42 -> 400 | G42: GC;DG | H42: LL1; LL2 ; LL3; LL5; LL6; LL7
B43: WVN / HAM / RTM / ANR / ZEE | C43: Yokohama | D43: =D42 -> 400 | E43: =E42 -> 400 | F43: =E43 -> 400 | G43: GC;DG | H43: LL1; LL2 ; LL3; LL5; LL6; LL7
B44: WVN / HAM / RTM / ANR / ZEE | C44: Osaka | D44: =D43 -> 400 | E44: =E42 -> 400 | F44: =E44 -> 400 | G44: GC;DG | H44: LL1; LL2 ; LL3; LL5; LL6; LL7
B46: Far East Wing Ports | C46: GATE IN subject to below + destination charges
B47: POD | C47: transshipment via | D47: 20' Box | E47: 40' Box | F47: 40' HQ | G47: GC;DG
B48: Akita, Akita, Japan | C48: Hibiki, Fukuoka, Japan | D48: 950 | E48: 1150 | F48: 1150 | G48: GC; DG
B49: Anji, Huzhou, Zhejiang, China | C49: Shanghai, China | D49: 200 | E49: 325 | F49: 325 | G49: GC; DG
B50: Anqing, Anqing, Anhui, China | C50: Shanghai, China | D50: 225 | E50: 325 | F50: 325 | G50: GC; DG
B51: Bandar Lampung, Lampung, Indonesia | C51: Singapore, Singapore | D51: 450 | E51: 725 | F51: 725 | G51: GC; DG
...

Sheet LookupK
B1: Index | C1: Base Port | D1: Port Group 1 | E1: Region Group2
B2: =D2 -> FEBP | C2: Busan, South Korea | D2: FEBP | E2: n/a
B3: =D3 -> FEBP | C3: Nansha, Guangzhou, Guangdong, China | D3: FEBP | E3: n/a
B4: =D4 -> FEBP | C4: Ningbo, Ningbo, Zhejiang, China | D4: FEBP | E4: NCHN
B5: =D5 -> FEBP | C5: Port Klang, Selangor, Malaysia | D5: FEBP | E5: n/a
B6: =D6 -> FEBP | C6: Shanghai, China | D6: FEBP | E6: NCHN
B7: =D7 -> FEBP | C7: Shekou, Shenzhen, Guangdong, China | D7: FEBP | E7: n/a
B8: =D8 -> JED | C8: Jeddah, Makkah, Saudi Arabia | D8: JED | E8: MEAST
B9: =D9 -> FEBP | C9: Hong Kong, Hong Kong; Kaohsiung, Taiwan; Port Klang, Selangor, Malaysia; Singapore, Singapore | D9: FEBP | E9: Multiple | G9: * Filter Rechenblatt mit 'contains ;'
B10: =D10 -> FEBP | C10: Ningbo, Ningbo, Zhejiang, China; Port Klang, Selangor, Malaysia | D10: FEBP | E10: Multiple
B11: =D11 -> FEBP | C11: Qingdao, Qingdao, Shandong, China; Shanghai, China | D11: FEBP | E11: Multiple
B12: =D12 -> FEBP | C12: Hong Kong, Hong Kong; Nansha, Guangzhou, Guangdong, China | D12: FEBP | E12: Multiple
B13: =D13 -> FEBP | C13: Ningbo, Ningbo, Zhejiang, China; Port Klang, Selangor, Malaysia | D13: FEBP | E13: Multiple
B14: FEBP | C14: Port Klang, Selangor, Malaysia; Shekou, Shenzhen, Guangdong, China | D14: FEBP | E14: Multiple
B15: =D15 -> FEBP | C15: Hong Kong, Hong Kong; Shekou, Shenzhen, Guangdong, China | D15: FEBP | E15: Multiple
B16: =D16 -> FEBP | C16: Nansha, Guangzhou, Guangdong, China; Yantian, Shenzhen, Guangdong, China | D16: FEBP | E16: Multiple
B17: =D17 -> FEBP | C17: Ningbo, Ningbo, Zhejiang, China; Shanghai, China | D17: FEBP | E17: Multiple
B18: =D18 -> FEBP | C18: Port Klang, Selangor, Malaysia; Singapore, Singapore | D18: FEBP | E18: Multiple
B19: =D19 -> FEBP | C19: Port Klang, Selangor, Malaysia; Shanghai, China | D19: FEBP | E19: Multiple
B20: =D20 -> FEBP | C20: Ningbo, Ningbo, Zhejiang, China; Shanghai, China | D20: FEBP | E20: Multiple
B21: =D21 -> HKG | C21: Hong Kong, Hong Kong, China | D21: HKG | E21: n/a
B22: =D22 -> SIN | C22: Singapore, Singapore | D22: SIN | E22: n/a
B23: =D23 -> FEBP | C23: Yantian, Shenzhen, Guangdong, China | D23: FEBP | E23: n/a
B24: FEBP | C24: Hong Kong, Hong Kong, China; Nansha, Guangzhou, Guangdong, China; Shekou, Shenzhen, Guangdong, China; Yantian, Shenzhen, Guangdong, China | D24: FEBP | E24: Multiple
B25: FEBP | C25: Ningbo, Ningbo, Zhejiang, China; Xiamen, Xiamen, Fujian, China | D25: FEBP | E25: n/a
B26: FEBP | C26: Kaohsiung, Taiwan; Port Klang, Selangor, Malaysia; Singapore, Singapore | D26: FEBP | E26: Multiple
B27: FEBP | C27: Hong Kong, Hong Kong, China; Nansha, Guangzhou, Guangdong, China; Shekou, Shenzhen, Guangdong, China | D27: FEBP | E27: Multiple
B28: FEBP | C28: Shekou, Shenzhen, Guangdong, China; Yantian, Shenzhen, Guangdong, China | D28: FEBP | E28: Multiple
B29: FEBP | C29: Ningbo, Ningbo, Zhejiang, China; Qingdao, Qingdao, Shandong, China; Shanghai, China | D29: FEBP | E29: Multiple
B30: FEBP | C30: Nansha, Guangzhou, Guangdong, China; Shekou, Shenzhen, Guangdong, China; Yantian, Shenzhen, Guangdong, China | D30: FEBP | E30: Multiple
B31: FEBP | C31: Nansha, Guangzhou, Guangdong, China; Shekou, Shenzhen, Guangdong, China | D31: FEBP | E31: Multiple
B32: FEBP | C32: Kaohsiung, Taiwan; Port Klang, Selangor, Malaysia | D32: FEBP | E32: Multiple
B33: FEBP | C33: Kaohsiung, Taiwan; Taipei, Taiwan | D33: FEBP | E33: Multiple
B34: FEBP | C34: Xingang, Tianjin, China | D34: FEBP | E34: Multiple
B35: FEBP | C35: Hong Kong, Hong Kong, China; Kaohsiung, Taiwan; Port Klang, Selangor, Malaysia | D35: FEBP | E35: Multiple
... B89: FEBP | C89: Hong Kong, Hong Kong, China; Nansha, Guangzhou, Guangdong, China; Shekou, Shenzhen, Guangdong, China; Yantian, Shenzhen, Guangdong, China | D89: FEBP | E89: Multiple

Sheet Rechenblatt Koper neu
B1: check ports under tab 'LookupK'
B2: direct calls - port group | C2: 20' | D2: 40' | E2: 40'HQ
B3: FEBP | C3: 50 | D3: 75 | E3: 75 | G3: = NUR HIER EINTRAGEN
G4: = DO NOT TOUCH!
B5: JED | C5: 550 | D5: 725 | E5: 725
B7: HKG | C7: 100 | D7: 175 | E7: 175 | G7: Dalian , Xingang nicht bei Over Ports?
B8: SIN | C8: 100 | D8: 175 | E8: 175
K11: 2 | L11: 3 | M11: 4
A12: Middle East | G12: OVER (BP Rate) | H12: TAD20ft | I12: TAD40ft | J12: TAD40HQ | K12: Rate 20ft | L12: Rate 40ft | M12: Rate 40HQ
A13: Port group | B13: TAD's Far East vom Aug 2018 - sortiert nach HUB-Port
A14: =VLOOKUP(G14,[1]LookupK!C:D,2,0) -> JED | B14: Al 'Aqabah, Jordan | C14: CY | G14: Jeddah, Makkah, Saudi Arabia | H14: 400 | I14: 600 | J14: 600 | K14: =IF(H14<>"",VLOOKUP($A14,$B$3:$E$10,2,FALSE)+H14,"--") -> 950 | L14: =IF(I14<>"",VLOOKUP($A14,$B$3:$E$10,3,FALSE)+I14,"--") -> 1325 | M14: =IF(J14<>"",VLOOKUP($A14,$B$3:$E$10,4,FALSE)+J14,"--") -> 1325
B20: TAD's Far East vom May 2025 - sortiert nach HUB-Port
A21: Asia Port Group | B21: Location | C21: Mode | D21: T/S Via | G21: OVER (BP Rate) | H21: TAD20ft | I21: TAD40ft | J21: TAD40HQ | K21: Rate 20ft | L21: Rate 40ft | M21: Rate 40HQ
A22: =VLOOKUP(G22,LookupK!C:D,2,0) -> FEBP | B22: Anji, Huzhou, Zhejiang, China | C22: CY | D22: Shanghai, China | E22: GC; DG | G22: Shanghai, China | H22: 175 | I22: 300 | J22: 300 | K22: =IF(H22<>"",VLOOKUP($A22,$B$3:$E$10,2,FALSE)+H22,"--") -> 225 | L22: =IF(I22<>"",VLOOKUP($A22,$B$3:$E$10,3,FALSE)+I22,"--") -> 375 | M22: =IF(J22<>"",VLOOKUP($A22,$B$3:$E$10,4,FALSE)+J22,"--") -> 375
A23: =VLOOKUP(G23,LookupK!C:D,2,0) -> FEBP | B23: Anqing, Anqing, Anhui, China | C23: CY | D23: Shanghai, China | E23: GC; DG | G23: Shanghai, China | H23: 200 | I23: 300 | J23: 300 | K23: =IF(H23<>"",VLOOKUP($A23,$B$3:$E$10,2,FALSE)+H23,"--") -> 250 | L23: =IF(I23<>"",VLOOKUP($A23,$B$3:$E$10,3,FALSE)+I23,"--") -> 375 | M23: =IF(J23<>"",VLOOKUP($A23,$B$3:$E$10,4,FALSE)+J23,"--") -> 375
A24: =VLOOKUP(G24,LookupK!C:D,2,0) -> FEBP | B24: Bangkok, Thailand | C24: CY | D24: Port Klang, Selangor, Malaysia | E24: GC; DG | G24: Port Klang, Selangor, Malaysia | H24: 225 | I24: 350 | J24: 350 | K24: =IF(H24<>"",VLOOKUP($A24,$B$3:$E$10,2,FALSE)+H24,"--") -> 275 | L24: =IF(I24<>"",VLOOKUP($A24,$B$3:$E$10,3,FALSE)+I24,"--") -> 425 | M24: =IF(J24<>"",VLOOKUP($A24,$B$3:$E$10,4,FALSE)+J24,"--") -> 425
A25: =VLOOKUP(G25,LookupK!C:D,2,0) -> FEBP | B25: Belawan, Sumatera Utara, Indonesia | C25: CY | D25: Port Klang, Selangor, Malaysia | E25: GC; DG | G25: Port Klang, Selangor, Malaysia | H25: 300 | I25: 475 | J25: 475 | K25: =IF(H25<>"",VLOOKUP($A25,$B$3:$E$10,2,FALSE)+H25,"--") -> 350 | L25: =IF(I25<>"",VLOOKUP($A25,$B$3:$E$10,3,FALSE)+I25,"--") -> 550 | M25: =IF(J25<>"",VLOOKUP($A25,$B$3:$E$10,4,FALSE)+J25,"--") -> 550
A26: =VLOOKUP(G26,LookupK!C:D,2,0) -> FEBP | B26: Bintulu, Sarawak, Malaysia | C26: CY | D26: Port Klang, Selangor, Malaysia | E26: GC; DG | G26: Port Klang, Selangor, Malaysia | H26: 750 | I26: 1350 | J26: 1350 | K26: =IF(H26<>"",VLOOKUP($A26,$B$3:$E$10,2,FALSE)+H26,"--") -> 800 | L26: =IF(I26<>"",VLOOKUP($A26,$B$3:$E$10,3,FALSE)+I26,"--") -> 1425 | M26: =IF(J26<>"",VLOOKUP($A26,$B$3:$E$10,4,FALSE)+J26,"--") -> 1425
A27: =VLOOKUP(G27,LookupK!C:D,2,0) -> FEBP | B27: Busan, South Korea | C27: CY | D27: Shanghai, China | E27: GC; DG | G27: Shanghai, China | H27: 45 | I27: 65 | J27: 65 | K27: =IF(H27<>"",VLOOKUP($A27,$B$3:$E$10,2,FALSE)+H27,"--") -> 95 | L27: =IF(I27<>"",VLOOKUP($A27,$B$3:$E$10,3,FALSE)+I27,"--") -> 140 | M27: =IF(J27<>"",VLOOKUP($A27,$B$3:$E$10,4,FALSE)+J27,"--") -> 140
A28: =VLOOKUP(G28,LookupK!C:D,2,0) -> FEBP | B28: Changde, Changde, Hunan, China | C28: CY | D28: Shanghai, China | E28: GC; DG | G28: Shanghai, China | H28: 375 | I28: 700 | J28: 700 | K28: =IF(H28<>"",VLOOKUP($A28,$B$3:$E$10,2,FALSE)+H28,"--") -> 425 | L28: =IF(I28<>"",VLOOKUP($A28,$B$3:$E$10,3,FALSE)+I28,"--") -> 775 | M28: =IF(J28<>"",VLOOKUP($A28,$B$3:$E$10,4,FALSE)+J28,"--") -> 775
A29: =VLOOKUP(G29,LookupK!C:D,2,0) -> FEBP | B29: Changsha, Changsha, Hunan, China | C29: CY | D29: Shanghai, China | E29: GC; DG | G29: Shanghai, China | H29: 325 | I29: 550 | J29: 550 | K29: =IF(H29<>"",VLOOKUP($A29,$B$3:$E$10,2,FALSE)+H29,"--") -> 375 | L29: =IF(I29<>"",VLOOKUP($A29,$B$3:$E$10,3,FALSE)+I29,"--") -> 625 | M29: =IF(J29<>"",VLOOKUP($A29,$B$3:$E$10,4,FALSE)+J29,"--") -> 625
A30: =VLOOKUP(G30,LookupK!C:D,2,0) -> FEBP | B30: Changshu, Suzhou, Jiangsu, China | C30: CY | D30: Shanghai, China | E30: GC; DG | G30: Shanghai, China | H30: 175 | I30: 275 | J30: 275 | K30: =IF(H30<>"",VLOOKUP($A30,$B$3:$E$10,2,FALSE)+H30,"--") -> 225 | L30: =IF(I30<>"",VLOOKUP($A30,$B$3:$E$10,3,FALSE)+I30,"--") -> 350 | M30: =IF(J30<>"",VLOOKUP($A30,$B$3:$E$10,4,FALSE)+J30,"--") -> 350
A31: =VLOOKUP(G31,LookupK!C:D,2,0) -> FEBP | B31: Changzhou, Changzhou, Jiangsu, China | C31: CY | D31: Shanghai, China | E31: GC; DG | G31: Shanghai, China | H31: 175 | I31: 300 | J31: 300 | K31: =IF(H31<>"",VLOOKUP($A31,$B$3:$E$10,2,FALSE)+H31,"--") -> 225 | L31: =IF(I31<>"",VLOOKUP($A31,$B$3:$E$10,3,FALSE)+I31,"--") -> 375 | M31: =IF(J31<>"",VLOOKUP($A31,$B$3:$E$10,4,FALSE)+J31,"--") -> 375
A32: =VLOOKUP(G32,LookupK!C:D,2,0) -> FEBP | B32: Chengdu, Chengdu, Sichuan, China | C32: CY | D32: Shanghai, China | E32: GC; DG | G32: Shanghai, China | H32: 1250 | I32: 1600 | J32: 1600 | K32: =IF(H32<>"",VLOOKUP($A32,$B$3:$E$10,2,FALSE)+H32,"--") -> 1300 | L32: =IF(I32<>"",VLOOKUP($A32,$B$3:$E$10,3,FALSE)+I32,"--") -> 1675 | M32: =IF(J32<>"",VLOOKUP($A32,$B$3:$E$10,4,FALSE)+J32,"--") -> 1675
A33: =VLOOKUP(G33,LookupK!C:D,2,0) -> FEBP | B33: Chongqing, China | C33: CY | D33: Shanghai, China | E33: GC; DG | G33: Shanghai, China | H33: 400 | I33: 725 | J33: 725 | K33: =IF(H33<>"",VLOOKUP($A33,$B$3:$E$10,2,FALSE)+H33,"--") -> 450 | L33: =IF(I33<>"",VLOOKUP($A33,$B$3:$E$10,3,FALSE)+I33,"--") -> 800 | M33: =IF(J33<>"",VLOOKUP($A33,$B$3:$E$10,4,FALSE)+J33,"--") -> 800
... A120: =VLOOKUP(G120,LookupK!C:D,2,0) -> FEBP | B120: Zhuhai, Zhuhai, Guangdong, China | C120: CY | D120: Shekou, Shenzhen, Guangdong, China | E120: GC; DG | G120: Shekou, Shenzhen, Guangdong, China | H120: 225 | I120: 350 | J120: 350 | K120: =IF(H120<>"",VLOOKUP($A120,$B$3:$E$10,2,FALSE)+H120,"--") -> 275 | L120: =IF(I120<>"",VLOOKUP($A120,$B$3:$E$10,3,FALSE)+I120,"--") -> 425 | M120: =IF(J120<>"",VLOOKUP($A120,$B$3:$E$10,4,FALSE)+J120,"--") -> 425

Sheet Koper+Trieste
B3: Orient Overseas Container Line Ltd.
B4: =Introduction!D8 -> NEW: rate reference mentioned in your email
B5: =Introduction!B9 -> valid as from 01.12.2025 - 31.01.2026
B9: FAR EAST (direct calls) | C9: GATE IN subject to below + destination charges
B10: POL | C10: POD | D10: 20' GP | E10: 40' GP | F10: 40' HQ | G10: GC; DG
B11: Koper; Trieste | C11: Ningbo | D11: 50 | E11: 75 | F11: =E11 -> 75 | G11: DG; GC
B12: Koper; Trieste | C12: Port Klang | D12: =D11 -> 50 | E12: =E11 -> 75 | F12: =E12 -> 75 | G12: DG; GC
B13: Koper; Trieste | C13: Busan | D13: =D11 -> 50 | E13: =E11 -> 75 | F13: =E13 -> 75 | G13: DG; GC
B14: Koper; Trieste | C14: Shanghai | D14: =D11 -> 50 | E14: =E11 -> 75 | F14: =E14 -> 75 | G14: DG; GC
B15: Koper; Trieste | C15: Shekou | D15: =D11 -> 50 | E15: =E11 -> 75 | F15: =E15 -> 75 | G15: DG; GC
B16: Koper; Trieste | C16: Kaohsiung | D16: 100 | E16: 175 | F16: =E16 -> 175 | G16: DG; GC
B17: Koper; Trieste | C17: Hong Kong | D17: =D16 -> 100 | E17: =E16 -> 175 | F17: =E17 -> 175 | G17: DG; GC
B18: Koper; Trieste | C18: Qingdao | D18: =D17 -> 100 | E18: =E16 -> 175 | F18: =E18 -> 175 | G18: DG; GC
B19: Koper; Trieste | C19: Singapore | D19: =D17 -> 100 | E19: =E18 -> 175 | F19: =E19 -> 175 | G19: DG; GC
B20: Koper; Trieste | C20: Dalian | D20: =D17 -> 100 | E20: =E16 -> 175 | F20: =E20 -> 175 | G20: DG; GC
B21: Koper; Trieste | C21: Xingang | D21: =D17 -> 100 | E21: =E16 -> 175 | F21: =E21 -> 175 | G21: DG; GC
B23: Koper; Trieste | C23: Jeddah | D23: 550 | E23: 725 | F23: =E23 -> 725 | G23: DG; GC
B25: Australia / New Zealand (via Port Klang) | C25: GATE IN subject to below + destination charges
B26: POL | C26: POD | D26: 20' GP | E26: 40' GP | F26: 40' HQ | G26: GC; DG
B27: Koper; Trieste | C27: Adelaide | D27: 1005 | E27: 1505 | F27: 1505 | G27: DG; GC
B28: Koper; Trieste | C28: Fremantle | D28: 1005 | E28: 1505 | F28: 1505 | G28: DG; GC
B29: Koper; Trieste | C29: Brisbane | D29: 1005 | E29: 1505 | F29: 1505 | G29: DG; GC
B30: Koper; Trieste | C30: Melbourne | D30: 1005 | E30: 1505 | F30: 1505 | G30: DG; GC
B31: Koper; Trieste | C31: Sydney | D31: 1005 | E31: 1505 | F31: 1505 | G31: DG; GC
B32: Koper; Trieste | C32: Forrestfield (via Fremantle) | D32: =D27+305 -> 1310 | E32: =E27+405 -> 1910 | F32: =F27+405 -> 1910 | G32: DG; GC
B34: Koper; Trieste | C34: Auckland | D34: 1380 | E34: 1980 | F34: =E34 -> 1980 | G34: DG; GC
B35: Koper; Trieste | C35: Lyttelton | D35: 1380 | E35: =E34 -> 1980 | F35: =E35 -> 1980 | G35: DG; GC
B36: Koper; Trieste | C36: Tauranga | D36: 1380 | E36: =E34 -> 1980 | F36: =E36 -> 1980 | G36: DG; GC
B37: Koper; Trieste | C37: Napier | D37: 1380 | E37: =E34 -> 1980 | F37: =E37 -> 1980 | G37: DG; GC
B40: Far East Wing Ports | C40: GATE IN subject to below + destination charges
B41: POD | C41: via transshipment | D41: 20' GP | E41: 40' GP | F41: 40' HQ | G41: GC; DG
B42: Anji, Huzhou, Zhejiang, China | C42: Shanghai, China | D42: 225 | E42: 375 | F42: 375 | G42: GC; DG
B43: Anqing, Anqing, Anhui, China | C43: Shanghai, China | D43: 250 | E43: 375 | F43: 375 | G43: GC; DG
B44: Bangkok, Thailand | C44: Port Klang, Selangor, Malaysia | D44: 275 | E44: 425 | F44: 425 | G44: GC; DG
B45: Belawan, Sumatera Utara, Indonesia | C45: Port Klang, Selangor, Malaysia | D45: 350 | E45: 550 | F45: 550 | G45: GC; DG
B46: Bintulu, Sarawak, Malaysia | C46: Port Klang, Selangor, Malaysia | D46: 800 | E46: 1425 | F46: 1425 | G46: GC; DG
B47: Busan, South Korea | C47: Shanghai, China | D47: 95 | E47: 140 | F47: 140 | G47: GC; DG
B48: Changde, Changde, Hunan, China | C48: Shanghai, China | D48: 425 | E48: 775 | F48: 775 | G48: GC; DG
B49: Changsha, Changsha, Hunan, China | C49: Shanghai, China | D49: 375 | E49: 625 | F49: 625 | G49: GC; DG
B50: Changshu, Suzhou, Jiangsu, China | C50: Shanghai, China | D50: 225 | E50: 350 | F50: 350 | G50: GC; DG
...

Sheet Intra Europe
B3: Orient Overseas Container Line Ltd.
B4: =Introduction!D8 -> NEW: rate reference mentioned in your email
B5: =Introduction!B9 -> valid as from 01.12.2025 - 31.01.2026
B9: NET Turkey Service | D9: GATE IN subject to below + destination charges
B10: POL | C10: POD | D10: 20' Box | E10: 40' Box | F10: 40' HQ | G10: Loop
B11: HAM / BHV / ANR | C11: Istanbul (Kumport) | D11: 350 | E11: 250 | F11: =E11 -> 250 | G11: NET
B12: HAM / BHV / ANR | C12: Korfez (DP World Yarimca) | D12: =D11 -> 350 | E12: =E11 -> 250 | F12: =E12 -> 250 | G12: NET
B13: HAM / BHV / ANR | C13: Gemlik | D13: =D11 -> 350 | E13: =E11 -> 250 | F13: =E13 -> 250 | G13: NET
B14: HAM / BHV / ANR | C14: Aliaga (Izmir) | D14: =D13 -> 350 | E14: =E11 -> 250 | F14: =E14 -> 250 | G14: NET
B16: HAM / BHV / ANR | C16: Piraeus | D16: 485 | E16: 520 | F16: =E16 -> 520 | G16: NET
B17: RTM | C17: Piraeus | D17: 535 | E17: 695 | F17: =E17 -> 695 | G17: NET
B18: RTM | C18: Piraeus | D18: 450 | E18: 520 | F18: =E18 -> 520 | G18: NET2
B20: RTM / HAM / ANR | C20: Mersin | D20: 400 | E20: =F20 -> 450 | F20: 450 | G20: NET2
B21: RTM / HAM / ANR | C21: Iskenderun | D21: 450 | E21: 500 | F21: =E21 -> 500 | G21: NET2
B22: RTM / HAM / ANR | C22: El Dekheila | D22: 525 | E22: 650 | F22: =E22 -> 650 | G22: NET2
B24: HAM / RTM / ANR | C24: Ashdod (via Piraeus) | D24: 1100 | E24: 1300 | F24: =E24 -> 1300 | G24: NET; NET2
B25: HAM / RTM / ANR | C25: Haifa (via Piraeus) | D25: 1100 | E25: 1200 | F25: =E25 -> 1200 | G25: NET; NET2
B27: Included charges: BAF; LSA; THC
B28: -------------------------------------------
B29: plus following surcharges, valid until further notice
B31: ETS: | C31: December EUR 34,- per TEU // January EUR 53,- per TEU - Emission Trading System (floating)
B32: MBF: | C32: EUR 40,- per booking (for non-Electronic Booking Instruction, except bookings to Russia until further notice)
B33: AMS: | C33: USD 30,- per BL - shipments to/via Turkey & Egypt
B34: DOC: | C34: EUR 75,- per B/L (applies for non-Electronic Shipping Instruction only via My OOCL.com)
B35: WRP: | C35: USD 45,- per TEU War Risk Premium for all containers to and from Israel eff. 1st November 2024
B36: IMO | C36: EUR 150,-/150,-/150,- per 20’/40’/40’HQ DRY - subject to acceptance
B37: heavy weight add. | C37: EUR 100,- per 20' >= 21tons payload (except NET Loop)
B39: Plus origin charges (all listed on www.oocl.com/eng/resourcecenter/globalinfo/Pages/default.aspx )
B40: Plus destination charges (all listed on www.oocl.com/eng/resourcecenter/globalinfo/Pages/default.aspx )
B42: RATE DATE IS GATE IN DATE
B44: Freight prepaid only

Sheet Middle East
B3: Orient Overseas Container Line Ltd.
B4: =Introduction!D8 -> NEW: rate reference mentioned in your email
B5: =Introduction!B9 -> valid as from 01.12.2025 - 31.01.2026
F9: remark: no hazardous cargo on IP service!
B10: MIDDLE EAST (direct calls) | C10: GATE IN subject to below + destination charges
B11: POL | C11: POD | D11: 20' Box | E11: 40' Box | F11: 40' HQ | G11: GC;DG | H11: Loop
B12: HAM / RTM / ANR | C12: Jebel Ali, Dubai, United Arab Emirates | D12: 575 | E12: 575 | F12: =E12 -> 575 | G12: GC;DG | H12: IP1
B13: HAM / RTM / ANR | C13: Abu Dhabi, United Arab Emirates | D13: 575 | E13: 575 | F13: =E13 -> 575 | G13: GC;DG | H13: IP1
B15: MIDDLE EAST Wing Ports | C15: GATE IN subject to below + destination charges
B16: POD | C16: transshipment via | D16: 20' Box | E16: 40' Box | F16: 40' HQ | G16: GC;DG
B17: Ajman, United Arab Emirates | C17: Jebel Ali, Dubai, United Arab Emirates | D17: 875 | E17: 1025 | F17: 1025 | G17: GC;DG | H17: IP1
B18: Al Hidd, Muharraq Governorate, Bahrain | C18: Jebel Ali, Dubai, United Arab Emirates | D18: 825 | E18: 925 | F18: 925 | G18: GC;DG | H18: IP1
B19: Al Shuwaikh, Al Asamah, Kuwait | C19: Jebel Ali, Dubai, United Arab Emirates | D19: 900 | E19: 1150 | F19: 1150 | G19: GC;DG | H19: IP1
B20: Ar Riyad, Ar Riyad, Saudi Arabia | C20: Dammam, Ash Sharqiyah, Saudi Arabia | D20: 1175 | E20: 1575 | F20: 1575 | G20: GC;DG | H20: IP1
B21: Dammam, Ash Sharqiyah, Saudi Arabia | C21: Jebel Ali, Dubai, United Arab Emirates | D21: 925 | E21: 1125 | F21: 1125 | G21: GC;DG | H21: IP1
B22: Hamad port, Al Wakrah, Qatar | C22: Jebel Ali, Dubai, United Arab Emirates | D22: 950 | E22: 1050 | F22: 1050 | G22: GC;DG | H22: IP1
B23: Kuwait, Al Asamah, Kuwait | C23: Jebel Ali, Dubai, United Arab Emirates | D23: 900 | E23: 1150 | F23: 1150 | G23: GC;DG | H23: IP1
B24: Sharjah, United Arab Emirates | C24: Jebel Ali, Dubai, United Arab Emirates | D24: 725 | E24: 850 | F24: 850 | G24: GC;DG | H24: IP1
B25: Shuaiba, Al Ahmadi, Kuwait | C25: Jebel Ali, Dubai, United Arab Emirates | D25: 900 | E25: 1125 | F25: 1125 | G25: GC;DG | H25: IP1
B26: Sohar, Al Batinah North Governorate, Oman | C26: Jebel Ali, Dubai, United Arab Emirates | D26: 825 | E26: 925 | F26: 925 | G26: GC;DG | H26: IP1
B27: Umm Al Quwain, United Arab Emirates | C27: Jebel Ali, Dubai, United Arab Emirates | D27: 925 | E27: 1175 | F27: 1175 | G27: GC;DG | H27: IP1
B29: Included charges: BAF; CAF; CWX; CWC; EMS; ETS; GAS; LSA: SUZ; IFP; THC
B30: -------------------------------------------
B31: plus following surcharges, valid until further notice
B33: WRS (War Risk Surcharge): | C33: USD 50,- per TEU (except Jeddah)
B34: MBF: | C34: EUR 40,- per booking (for non-Electronic Booking Instruction, except bookings to Russia until further notice)
B35: DOC: | C35: EUR 75,- per B/L (applies for non-Electronic Shipping Instruction only via My OOCL.com)
B36: IMO: | C36: USD 75,- per CTR (dry) (subject to acceptance)
B38: Plus origin charges (all listed on www.oocl.com/eng/resourcecenter/globalinfo/Pages/default.aspx )
B39: Plus destination charges (all listed on www.oocl.com/eng/resourcecenter/globalinfo/Pages/default.aspx )
B41: RATE DATE IS SAILING DATE
B43: Freight prepaid only

Sheet Africa
B3: Orient Overseas Container Line Ltd.
B4: =Introduction!D8 -> NEW: rate reference mentioned in your email
B5: =Introduction!B9 -> valid as from 01.12.2025 - 31.01.2026
B9: EUR Payment!
B10: WEST AFRICA | C10: GATE IN subject to below + destination charges
B11: POL | C11: POD | D11: transshipment via | E11: 20' Box | F11: 40' Box | G11: 40' HQ | H11: GC;DG | I11: Loop
B12: HAM / RTM / ANR | C12: Abidjan (Ivory Coast) | D12: Algeciras | E12: 1075 | F12: 1550 | G12: =F12 -> 1550 | H12: GC;DG | I12: EEX; IP1
B13: HAM / RTM / ANR | C13: Apapa (Lagos - Nigeria)* | D13: Tema | E13: 2275 | F13: 2950 | G13: =F13 -> 2950 | H13: GC;DG | I13: EEX; IP1
B14: HAM / RTM / ANR | C14: Cotonou (Benin) | D14: Tema | E14: 1525 | F14: 1750 | G14: =F14 -> 1750 | H14: GC;DG | I14: EEX; IP1
B15: HAM / RTM / ANR | C15: Dakar (Senegal) | D15: Algeciras | E15: 1475 | F15: 1800 | G15: =F15 -> 1800 | H15: GC;DG | I15: EEX; IP1
B16: HAM / RTM / ANR | C16: Lekki (Nigeria) | D16: Tema | E16: 2275 | F16: 2950 | G16: =F16 -> 2950 | H16: GC;DG | I16: EEX; IP1
B17: HAM / RTM / ANR | C17: Lome (Togo) | D17: Tema | E17: 1525 | F17: 1750 | G17: =F17 -> 1750 | H17: GC;DG | I17: EEX; IP1
B18: HAM / RTM / ANR | C18: Tema (Ghana) | D18: Algeciras | E18: 1525 | F18: 1850 | G18: =F18 -> 1850 | H18: GC;DG | I18: EEX; IP1
B20: EUR Payment!
B21: EAST AFRICA | C21: GATE IN subject to below + destination charges
B22: POL | C22: POD | D22: transshipment via | E22: 20' Box | F22: 40' Box | G22: 40' HQ | H22: GC;DG | I22: Loop
B23: HAM / RTM / ANR | C23: Mombasa (Kenya) | D23: Jebel Ali | E23: 1775 | F23: 2200 | G23: =F23 -> 2200 | H23: GC | I23: IP1
B24: HAM / RTM / ANR | C24: Beira (Mozambique) | D24: Jebel Ali | E24: 1775 | F24: 2200 | G24: 2200 | H24: GC | I24: IP1
B25: HAM / RTM / ANR | C25: Maputo (Mozambique) | D25: Jebel Ali | E25: 1775 | F25: 2200 | G25: 2200 | H25: GC | I25: IP1
B26: HAM / RTM / ANR | C26: Dar Es Salaam (Tanzania) | D26: Jebel Ali | E26: 1775 | F26: 2200 | G26: 2200 | H26: GC | I26: IP1
H27: *remark: no hazardous cargo on IP service!
B29: Included charges: CWC; CWX; THC; EBS
B30: -------------------------------------------
B31: plus following surcharges, valid until further notice
B33: ETS: | C33: December EUR 6,- per TEU // January EUR 13,- per TEU - Emission Trading System (floating)
B34: LSA: | C34: December EUR 124,- per TEU // January EUR 116,- per TEU - Low sulphur adjustment (floating)
B35: *PSS | C35: EUR 980,- per Cont. for Lagos only
B36: MBF: | C36: EUR 40,- per booking (for non-Electronic Booking Instruction, except bookings to Russia until further notice)
B37: DOC: | C37: EUR 75,- per B/L (applies for non-Electronic Shipping Instruction only via My OOCL.com)
B38: IMO: | C38: EUR 200,- per TEU (dry) (subject to acceptance)
B40: Plus origin charges (all listed on www.oocl.com/eng/resourcecenter/globalinfo/Pages/default.aspx )
B41: Plus destination charges (all listed on www.oocl.com/eng/resourcecenter/globalinfo/Pages/default.aspx )
B43: RATE DATE IS SAILING DATE

Sheet India+Pakistan
B3: Orient Overseas Container Line Ltd.
B4: =Introduction!D8 -> NEW: rate reference mentioned in your email
B5: =Introduction!B9 -> valid as from 01.12.2025 - 31.01.2026
G8: remark: no hazardous cargo on IP service!
B9: INDIA / PAKISTAN | C9: GATE IN subject to below + destination charges
B10: POL | C10: POD | D10: 20' Box | E10: 40' Box | F10: 40' HQ | G10: GC;DG | H10: Loop
B11: HAM / RTM / ANR | C11: Nhava Sheva / Mundra (direct service) | D11: 550 | E11: 550 | F11: 550 | G11: GC | H11: IP1
B12: HAM / RTM / ANR | C12: Karachi (direct service) ** | D12: 800 | E12: 850 | F12: =E12 -> 850 | G12: GC | H12: IP1
B13: RTM / HAM / ANR | C13: Haldia (via Colombo) | D13: 1125 | E13: 1650 | F13: =E13 -> 1650 | G13: GC | H13: LL6
B14: RTM / HAM / ANR / WVN / ZEE | C14: Kolkata (via Port Klang / Singapore) | D14: =D13 -> 1125 | E14: =E13 -> 1650 | F14: =F13 -> 1650 | G14: GC | H14: LL1; LL5; LL6; LL7
B15: RTM / HAM / ANR | C15: Tuticorin (via Colombo) | D15: 650 | E15: 750 | F15: =E15 -> 750 | G15: GC | H15: LL6
B18: Far East direct calls & transshipments | C18: GATE IN GATE OUT subject to below + destination charges (all charges prepaid!)
B19: POL | C19: POD | D19: 20' Box | E19: 40' Box | F19: 40' HQ | G19: GC;DG | H19: Loop
B20: WVN / HAM / ZEE / RTM | C20: Chattogram (via Port Klang / Singapore / Colombo) | D20: 1300 | E20: 1600 | F20: 1600 | G20: GC;DG | H20: LL1; LL3; LL5; LL6; LL7
B21: HAM / RTM | C21: Colombo | D21: 550 | E21: 550 | F21: 550 | G21: GC;DG | H21: LL6
B23: ONCARRIAGE (ICD) | C23: REMARK: 18,00 % GST (Goods Service Tax) applicable on collect basis (vatos)
B24: harmless cargo ONLY!!!
B25: Pls see b.m. link:
B27: OOCL - Local Surcharges / Inland Haulage Tariff
B29: INDIA FREETIME
B30: 14 calendar days DET/DEM combined (2 in 1) free in port of discharge and ICD’s (excl port storage)
B31: OOCL - Demurrage & Detention Free Time and Charges
B34: Included charges: BAF; CAF; CWX; EMS; ETS; GAS; LSA: SUZ; IFP; THC
B35: -------------------------------------------
B36: plus following surcharges, valid until further notice
B38: MBF: | C38: EUR 40,- per booking (for non-Electronic Booking Instruction, except bookings to Russia until further notice)
B39: DOC: | C39: EUR 75,- per B/L (applies for non-Electronic Shipping Instruction only via My OOCL.com)
B40: IMO to Chattogram / Colombo on LL-services only: | C40: USD 100,- per CTR (dry) subject to PSA costs if transshipped via Singapore (subject to acceptance) ; except Malaysia
B41: *CWC applicable for Haldia/Kolkata only: | C41: USD 175,- per 20'GP >= 24 tons payload
B42: CLE Colombo (Cleaning Fee): | C42: USD 10,- per TEU prepaid
B43: CLE Chattogram (Cleaning Fee): | C43: BDT 500,- per CTR prepaid
B44: ** RES Karachi (Routing Emergency Surcharge) | C44: USD 200,- per CTR eff 6th May 2025
B46: Plus origin charges (all listed on www.oocl.com/eng/resourcecenter/globalinfo/Pages/default.aspx )
B47: Plus destination charges (all listed on www.oocl.com/eng/resourcecenter/globalinfo/Pages/default.aspx )
B49: PSA additionals
B50: Please note following PSA additional will be charged for transshipment via Singapore:
B52: PSA = DHT tariff per 20’/40’/45’ for DG t/s via SIN
B53: · PSA 3/2F/2S: SGD 180/360/405
B54: · PSA 2B/2C: SGD 930/1485/1643
B55: · PSA 2A: SGD 1080/1635/1793
...

Sheet Australia & New Zealand
B3: Orient Overseas Container Line Ltd.
B4: =Introduction!D8 -> NEW: rate reference mentioned in your email
B5: =Introduction!B9 -> valid as from 01.12.2025 - 31.01.2026
B9: AUSTRALIA | D9: GATE IN subject to below + destination charges
B10: POL | C10: POD | D10: Transshipment via | E10: 20' Box | F10: 40' Box | G10: 40' HQ
B11: WVN / HAM / RTM / ANR / ZEE | C11: Sydney | D11: Singapore / Port Klang | E11: 800 | F11: 1300 | G11: 1300
B12: WVN / HAM / RTM / ANR / ZEE | C12: Melbourne | D12: Singapore / Port Klang | E12: =E13 -> 800 | F12: =F11 -> 1300 | G12: =F12 -> 1300
B13: WVN / HAM / RTM / ANR / ZEE | C13: Brisbane | D13: Singapore / Port Klang | E13: =E11 -> 800 | F13: =F11 -> 1300 | G13: =F13 -> 1300
B14: WVN / HAM / RTM / ANR / ZEE | C14: Fremantle | D14: Singapore / Port Klang | E14: =E13 -> 800 | F14: =F11 -> 1300 | G14: =F14 -> 1300
B15: WVN / HAM / RTM / ANR / ZEE | C15: Adelaide | D15: Singapore / Port Klang | E15: =E14 -> 800 | F15: =F11 -> 1300 | G15: =F15 -> 1300
B16: WVN / HAM / RTM / ANR / ZEE | C16: Devonport | D16: via Singapore/Port Klang-Melbourne | E16: 2430 | F16: 3725 | G16: =F16 -> 3725
B17: WVN / HAM / RTM / ANR / ZEE | C17: Forrestfield | D17: via Fremantle | E17: =E15+305 -> 1105 | F17: =F15+405 -> 1705 | G17: =F17 -> 1705
B19: NEW ZEALAND | D19: GATE IN subject to below + destination charges
B20: POL | C20: POD | D20: Transshipment via | E20: 20' Box | F20: 40' Box | G20: 40' HQ
B21: WVN / HAM / RTM / ANR / ZEE | C21: Auckland | D21: Singapore / Port Klang | E21: 1150 | F21: 1500 | G21: =F21 -> 1500
B22: WVN / HAM / RTM / ANR / ZEE | C22: Lyttelton | D22: Singapore / Port Klang | E22: =E21 -> 1150 | F22: =F21 -> 1500 | G22: =F22 -> 1500
B23: WVN / HAM / RTM / ANR / ZEE | C23: Tauranga | D23: Singapore / Port Klang | E23: =E21 -> 1150 | F23: =F21 -> 1500 | G23: =F23 -> 1500
B24: WVN / HAM / RTM / ANR / ZEE | C24: Napier | D24: Singapore / Port Klang | E24: =E21 -> 1150 | F24: =F21 -> 1500 | G24: =F24 -> 1500
B25: WVN / HAM / RTM / ANR / ZEE | C25: Wellington | D25: Singapore / Port Klang | E25: =E21 -> 1150 | F25: =F21 -> 1500 | G25: =F25 -> 1500
B27: Included charges: BAF; CAF; CWC; CWX; EMS: GAS; SUZ; THC; IFP
B28: -------------------------------------------
B29: plus following surcharges, valid until further notice
B31: ETS: | C31: December USD 35,- per TEU // January USD 51,- per TEU - Emission Trading System (floating)
B32: LSA: | C32: December USD 237,- per TEU // January USD 213,- per TEU - Low sulphur adjustment (floating)
B33: MBF: | C33: EUR 40,- per booking (for non-Electronic Booking Instruction, except bookings to Russia until further notice)
B34: DOC: | C34: EUR 75,- per B/L (applies for non-Electronic Shipping Instruction only via My OOCL.com)
B35: AMS: | C35: EUR 25,- per B/L - shipments to/via Japan/China/Israel
B36: IMO: | C36: USD 150,-/200,-/200,- per 20’/40’/40’HQ (dry) – subject to PSA costs when transshipped via Singapore (subject to acceptance)
B38: Plus origin charges (all listed on www.oocl.com/eng/resourcecenter/globalinfo/Pages/default.aspx )
B39: Plus destination charges (all listed on www.oocl.com/eng/resourcecenter/globalinfo/Pages/default.aspx )
B41: For your PSA Group (to/via Singapore) please check with local OOCL Customer Service
B43: PSA costs = DHT tariff per 20’/40’/45’ for DG t/s via SIN valid till 31.01.2026
B44: · PSA 3/2F/2S: SGD 180/360/405
B45: · PSA 2B/2C: SGD 930/1485/1643
B46: · PSA 2A: SGD 1080/1635/1793
B47: · PSA 1S: SGD 380/560/605
B48: · PSA 1C/1N: SGD 1130/1685/1843
B49: · PSA 1/1D: SGD 1490/2405/2653
B50: · PSA 2 (UN1057 only): SGD 1690/2605/2853
B51: · PSA 2 (except UN1057): SGD 1290/2205/2453
...

Sheet Special Equipment
G4: Type | H4: max. length in gauge | I4: max. width in gauge | J4: max. height in gauge | K4: max. top loading width | L4: max. payload
G5: 20' OT | H5: 589 cm | I5: 235 cm | J5: 234 cm | K5: 220 cm | L5: 28.000 kos
G6: 40' OT | H6: 1203 cm | I6: 235 cm | J6: 234 cm | K6: 220 cm | L6: 26.500 kos
G7: 40' OQ | H7: 1203 cm | I7: 235 cm | J7: 265 cm | K7: 220 cm | L7: 26.500 kos | M7: OQ = Open Top High Cube
G8: 40'OQ max. cargo height = 247 cm if cargo width is >= 223 cm
G9: 20' FR | H9: 550 cm | I9: 244 cm | J9: 220 cm | K9: - | L9: 31.000 kos
G10: 40' FR | H10: 1150 cm* | I10: 244 cm | J10: 195 cm | K10: - | L10: 39.600 kos
G11: 40' FQ | H11: 1150 cm * | I11: 244 cm | J11: 226 cm | K11: - | L11: 47.300 kos | M11: FQ = Flat High Cube
G12: max. cargo width / height: 395 cm
G13: * if OW / OWOH
I15: Europe - Far East Ratesheet
I16: Service Contract Number: FE140000
E17: valid as from 01.01.2026 - 31.01.2026
X20: Restrictions
B21: POD | C21: POL | D21: T/S | E21: 20' OT/FR IG | F21: 20' OT/FR OH | G21: 20' FR(OW) | H21: 20' FR OH OW one side | I21: 20' FR OWOH | J21: 40' OT IG | K21: 40OQ IG | L21: 40' FR IG | M21: 40FQ IG | N21: 40' OT OH | O21: 40' OQ OH | P21: 40' FR OH | Q21: 40' FQ OH | R21: 40' FR OW | S21: 40' FQ OW | T21: 40' FR OH OW one side | U21: 40' FQ OH OW one side | V21: 40' FR OWOH | W21: 40' FQ OWOH | X21: Max payload / to | Y21: Max OW / cm (per side) | Z21: Max OH / cm
B23: Main Ports | C23: GATE IN + AMS / DOC fee where applicable + destination charges
B24: Dalian | C24: HAM / RTM / ANR | D24: direct | E24: 250 | F24: 750 | G24: 1050 | H24: 1450 | I24: 1550 | J24: 450 | K24: 550 | L24: 450 | M24: 550 | N24: 875 | O24: 975 | P24: 875 | Q24: 975 | R24: 1125 | S24: 1275 | T24: 1475 | U24: 1575 | V24: 1650 | W24: 1750 | X24: 34**
B25: Hong Kong | C25: HAM / RTM / ZEE | D25: direct | E25: 250 | F25: 750 | G25: 1050 | H25: 1450 | I25: 1550 | J25: 450 | K25: 550 | L25: 450 | M25: 550 | N25: 875 | O25: 975 | P25: 875 | Q25: 975 | R25: 1125 | S25: 1275 | T25: 1475 | U25: 1575 | V25: 1650 | W25: 1750 | X25: 34**
B26: Kaohsiung | C26: HAM / RTM | D26: direct | E26: 250 | F26: 750 | G26: 1050 | H26: 1450 | I26: 1550 | J26: 450 | K26: 550 | L26: 450 | M26: 550 | N26: 875 | O26: 975 | P26: 875 | Q26: 975 | R26: 1125 | S26: 1275 | T26: 1475 | U26: 1575 | V26: 1650 | W26: 1750 | X26: 34**
B27: Ningbo | C27: WVN / HAM / RTM / ANR / ZEE | D27: direct | E27: 250 | F27: 750 | G27: 1050 | H27: 1450 | I27: 1550 | J27: 450 | K27: 550 | L27: 450 | M27: 550 | N27: 875 | O27: 975 | P27: 875 | Q27: 975 | R27: 1125 | S27: 1275 | T27: 1475 | U27: 1575 | V27: 1650 | W27: 1750 | X27: 34**
B28: Port Klang | C28: HAM / RTM / ANR / ZEE | D28: direct | E28: 250 | F28: 750 | G28: 1050 | H28: 1450 | I28: 1550 | J28: 450 | K28: 550 | L28: 450 | M28: 550 | N28: 875 | O28: 975 | P28: 875 | Q28: 975 | R28: 1125 | S28: 1275 | T28: 1475 | U28: 1575 | V28: 1650 | W28: 1750 | X28: 34**
B29: Qingdao | C29: HAM / RTM / ANR / WVN / ZEE | D29: direct | E29: 250 | F29: 750 | G29: 1050 | H29: 1450 | I29: 1550 | J29: 450 | K29: 550 | L29: 450 | M29: 550 | N29: 875 | O29: 975 | P29: 875 | Q29: 975 | R29: 1125 | S29: 1275 | T29: 1475 | U29: 1575 | V29: 1650 | W29: 1750 | X29: 34**
B30: Shanghai | C30: WVN / HAM / RTM / ANR / ZEE | D30: direct | E30: 250 | F30: 750 | G30: 1050 | H30: 1450 | I30: 1550 | J30: 450 | K30: 550 | L30: 450 | M30: 550 | N30: 875 | O30: 975 | P30: 875 | Q30: 975 | R30: 1125 | S30: 1275 | T30: 1475 | U30: 1575 | V30: 1650 | W30: 1750 | X30: 34**
B31: Singapore | C31: ZEE / WVN /HAM / RTM /ANR | D31: direct | E31: 250 | F31: 750 | G31: 1050 | H31: 1450 | I31: 1550 | J31: 450 | K31: 550 | L31: 450 | M31: 550 | N31: 875 | O31: 975 | P31: 875 | Q31: 975 | R31: 1125 | S31: 1275 | T31: 1475 | U31: 1575 | V31: 1650 | W31: 1750 | X31: 34**
B32: Taipeh | C32: HAM / RTM | D32: direct | E32: 250 | F32: 750 | G32: 1050 | H32: 1450 | I32: 1550 | J32: 450 | K32: 550 | L32: 450 | M32: 550 | N32: 875 | O32: 975 | P32: 875 | Q32: 975 | R32: 1125 | S32: 1275 | T32: 1475 | U32: 1575 | V32: 1650 | W32: 1750 | X32: 34**
B33: Xingang | C33: HAM / RTM / ANR | D33: direct | E33: 250 | F33: 750 | G33: 1050 | H33: 1450 | I33: 1550 | J33: 450 | K33: 550 | L33: 450 | M33: 550 | N33: 875 | O33: 975 | P33: 875 | Q33: 975 | R33: 1125 | S33: 1275 | T33: 1475 | U33: 1575 | V33: 1650 | W33: 1750 | X33: 34**
B34: Xiamen | C34: WVN / HAM / RTM / ZEE | D34: direct | E34: 250 | F34: 750 | G34: 1050 | H34: 1450 | I34: 1550 | J34: 450 | K34: 550 | L34: 450 | M34: 550 | N34: 875 | O34: 975 | P34: 875 | Q34: 975 | R34: 1125 | S34: 1275 | T34: 1475 | U34: 1575 | V34: 1650 | W34: 1750 | X34: 34**
B35: Yantian | C35: HAM / RTM / ZEE / WVN | D35: direct | E35: 250 | F35: 750 | G35: 1050 | H35: 1450 | I35: 1550 | J35: 450 | K35: 550 | L35: 450 | M35: 550 | N35: 875 | O35: 975 | P35: 875 | Q35: 975 | R35: 1125 | S35: 1275 | T35: 1475 | U35: 1575 | V35: 1650 | W35: 1750 | X35: 34**
B36: Kobe / Nagoya /Tokyo / Yokohama / Osaka* | C36: HAM / RTM / ANR | D36: Port Klang | E36: 1100 | F36: 1700 | G36: 2300 | H36: 2650 | I36: 2850 | J36: 1425 | K36: 1525 | L36: 1425 | M36: 1525 | N36: 2125 | O36: 2225 | P36: 2125 | Q36: 2225 | R36: 2475 | S36: 2575 | T36: 3225 | U36: 3325 | V36: 3600 | W36: 3700 | X36: 29** | Y36: 20 | Z36: 180
B37: Kobe / Nagoya /Tokyo / Yokohama / Osaka* | C37: HAM / RTM / ANR | D37: Port Klang | E37: 1100 | F37: 2150 | G37: 2750 | H37: 3100 | I37: 3300 | J37: 1425 | K37: 1525 | L37: 1425 | M37: 1525 | N37: 2575 | O37: 2675 | P37: 2575 | Q37: 2675 | R37: 2925 | S37: 3025 | T37: 3675 | U37: 3775 | V37: 4050 | W37: 4150 | X37: 29** | Z37: 200
B38: Colombo (gigo all in incl. THD) | C38: HAM / RTM | D38: direct | E38: 250 | F38: 750 | G38: 1050 | H38: 1650 | I38: 1550 | J38: 450 | K38: 550 | L38: 450 | M38: 550 | N38: 875 | O38: 975 | P38: 875 | Q38: 975 | R38: 1125 | S38: 1275 | T38: 1775 | U38: 1875 | V38: 1650 | W38: 1750 | X38: 34**
B39: *direct delivery is a must for OOG at JAPAN | X39: **weight above on request!
B41: Australia Main Ports | C41: GATE IN + ETS / LSA / AMS / DOC fee where applicable + destination charges
B42: Brisbane / Sydney / Melbourne / Fremantle / Adelaide | C42: HAM / RTM / ANR | D42: Port Klang | E42: 1300 | F42: on request | G42: on request | H42: on request | I42: on request | J42: 2150 | K42: 2250 | L42: 2150 | M42: 2250 | N42: on request | O42: on request | P42: on request | Q42: on request | R42: on request | S42: on request | T42: on request | U42: on request | V42: on request | W42: on request | X42: 34 | Y42: 10 | Z42: 176
